Workbook
Name Dates: #REF!
Name Weeks: #REF!

Sheet Admin
A1: Username: | B1: shaughey

Sheet Huddle
B1: Date | C1: 46010 | F1: Week of | G1: 45999 | O1: =TODAY()-L3 -> 46024 | P1: =TODAY() -> 46034 | Q1: {=IFERROR(_xlfn._xlws.FILTER(_xlfn.UNIQUE('Call Activity'!O:O),(_xlfn.UNIQUE('Call Activity'!O:O)<>0)*(_xlfn.UNIQUE('Call Activity'!O:O)<>"Date")*(_xlfn.UNIQUE('Call Activity'!O:O)>36892)),"")} -> 45931 | R1: {=IFERROR(_xlfn._xlws.FILTER(_xlfn.UNIQUE('Agent Activity'!Q:Q),(_xlfn.UNIQUE('Agent Activity'!Q:Q)<>0)*(_xlfn.UNIQUE('Agent Activity'!Q:Q)<>"Week")*(_xlfn.UNIQUE('Agent Activity'!Q:Q)>36892)),"")} -> 45929 | S1: {=IFERROR(_xlfn._xlws.FILTER(Q:Q, (Q:Q > $O$1) * (Q:Q <= $P$1)),"No data")} -> No data | T1: {=IFERROR(_xlfn._xlws.FILTER(R:R, (R:R >= $O$2) * (R:R <= $P$2)),"No data")} -> No data | V1: {=IFERROR(_xlfn._xlws.FILTER('Call Activity'!K:K, ('Call Activity'!P:P = TEXT($C$1,"mmmm")) * ('Call Activity'!O:O <= $C$1)),"")} -> 2.7 | W1: {=IFERROR(_xlfn._xlws.FILTER( 'Call Activity'!K:K, ('Call Activity'!O:O >= $G$1) * ('Call Activity'!O:O <= ($G$1+5)) ),"")} -> 2.7 | X1: {=IFERROR(_xlfn._xlws.FILTER('Call Activity'!K:K, ('Call Activity'!P:P = TEXT($G$1,"mmmm")) * ('Call Activity'!O:O <= ($G$1+5))),"")} -> 2.7 | Z1: Name | AA1: Phone | AB1: (Available) | AC1: (raw) | AD1: {=IFERROR(_xlfn._xlws.SORT(_xlfn._xlws.FILTER(AA2:AA26,(Z2:Z26<>""))),"")} -> 20113 | AE1: {=IFERROR(_xlfn._xlws.SORT(_xlfn._xlws.FILTER(AA2:AA26,(Z2:Z26=""))),"")} -> 0 | AF1: Names (alph) | AG1: Ph (alph) | AI1: Nm (sort) | AJ1: Phone (sort)
N2: v 4.1.2 | O2: =(P1-WEEKDAY(P1,1)+2)-(L4*7) -> 46013 | P2: =P1-WEEKDAY(P1,1)+2 -> 46034 | Q2: 45932 | R2: 45936 | V2: 4.19 | W2: 4.19 | X2: 4.19 | Z2: Ruth | AA2: 20113 | AB2: =IF(AC2<>"",_xlfn.TEXTBEFORE(AC2," ("),"") -> 20112 | AC2: {=IFERROR(_xlfn.LET( _xlpm.list, TRIM('Agent Activity'!A5:A1000000), _xlpm.uniques, _xlfn.UNIQUE(_xlpm.list), _xlfn._xlws.SORT(_xlfn._xlws.FILTER(_xlpm.uniques, _xlpm.uniques<>"")) ),"")} -> 20112 (ID: 20112) | AD2: 20114 | AE2: 0 | AF2: {=IFERROR(_xlfn._xlws.SORT(_xlfn._xlws.FILTER(Z2:Z26,(Z2:Z26<>""))),"")} -> Allison | AG2: {=IFERROR(_xlfn.LET(_xlpm.exts,_xlfn.TOCOL(AD1:AE26,1,TRUE),_xlfn._xlws.FILTER(_xlpm.exts,_xlpm.exts<>0)),"")} -> 20113 | AI2: =IF(AJ2="","",IF(_xlfn.XLOOKUP(AJ2,$AA$2:$AA$26,$Z$2:$Z$26,"")=0,"",_xlfn.XLOOKUP(AJ2,$AA$2:$AA$26,$Z$2:$Z$26,""))) -> Ruth | AJ2: {=IFERROR(_xlfn._xlws.SORT(_xlfn._xlws.FILTER(AA2:AA26,(AA2:AA26<>""))),"")} -> 20113
B3: Calls In: | C3: =_xlfn.XLOOKUP($C$1,'Call Activity'!O:O,'Call Activity'!B:B,"") -> 118 | F3: Calls In: | G3: =SUMIF('Agent Activity'!Q:Q, $G$1, 'Agent Activity'!C:C) -> 712 | J3: Days before: | L3: 10 | Q3: 45933 | R3: 45943 | V3: 1.72 | W3: 1.72 | X3: 1.72 | Z3: Leah | AA3: 20114 | AB3: =IF(AC3<>"",_xlfn.TEXTBEFORE(AC3," ("),"") -> 20113 | AC3: 20113 (ID: 20113) | AD3: 20116 | AE3: 0 | AF3: Grey | AG3: 20114 | AI3: =IF(AJ3="","",IF(_xlfn.XLOOKUP(AJ3,$AA$2:$AA$26,$Z$2:$Z$26,"")=0,"",_xlfn.XLOOKUP(AJ3,$AA$2:$AA$26,$Z$2:$Z$26,""))) -> Leah | AJ3: 20114
B4: Abandoned: | C4: =_xlfn.XLOOKUP($C$1,'Call Activity'!O:O,'Call Activity'!J:J,"") -> 8 | F4: Abandoned: | G4: =SUMIF('Call Activity'!Q:Q, $G$1,'Call Activity'!J:J) -> 29 | J4: Weeks before: | L4: 3 | Q4: 45936 | R4: 45950 | V4: 4.11 | W4: 4.11 | X4: 4.11 | Z4: Grey | AA4: 20116 | AB4: =IF(AC4<>"",_xlfn.TEXTBEFORE(AC4," ("),"") -> 20114 | AC4: 20114 (ID: 20114) | AD4: 20118 | AE4: 0 | AF4: Karen | AG4: 20116 | AI4: =IF(AJ4="","",IF(_xlfn.XLOOKUP(AJ4,$AA$2:$AA$26,$Z$2:$Z$26,"")=0,"",_xlfn.XLOOKUP(AJ4,$AA$2:$AA$26,$Z$2:$Z$26,""))) -> Grey | AJ4: 20116
B5: Calls Out: | C5: =_xlfn.XLOOKUP($C$1,'Call Activity'!O:O,'Call Activity'!L:L,"") -> 99 | F5: Calls Out: | G5: =SUMIF('Call Activity'!Q:Q, $G$1, 'Call Activity'!L:L) -> 673 | N5: 3 | Q5: 45937 | R5: 45957 | V5: 7.89 | W5: 7.89 | X5: 7.89 | Z5: Nicole | AA5: 20118 | AB5: =IF(AC5<>"",_xlfn.TEXTBEFORE(AC5," ("),"") -> 20116 | AC5: 20116 (ID: 20116) | AD5: 20119 | AE5: 0 | AF5: Leah | AG5: 20118 | AI5: =IF(AJ5="","",IF(_xlfn.XLOOKUP(AJ5,$AA$2:$AA$26,$Z$2:$Z$26,"")=0,"",_xlfn.XLOOKUP(AJ5,$AA$2:$AA$26,$Z$2:$Z$26,""))) -> Nicole | AJ5: 20118
B6: Total Calls: | C6: =IFERROR(C3+C5-C4,"") -> 209 | F6: Total Calls: | G6: =SUM(G3+G5) -> 1385 | N6: 7 | Q6: 45938 | R6: 45964 | V6: 7.34 | X6: 7.34 | Z6: Nissa | AA6: 20119 | AB6: =IF(AC6<>"",_xlfn.TEXTBEFORE(AC6," ("),"") -> 20118 | AC6: 20118 (ID: 20118) | AD6: 20120 | AE6: 0 | AF6: Nicole | AG6: 20119 | AI6: =IF(AJ6="","",IF(_xlfn.XLOOKUP(AJ6,$AA$2:$AA$26,$Z$2:$Z$26,"")=0,"",_xlfn.XLOOKUP(AJ6,$AA$2:$AA$26,$Z$2:$Z$26,""))) -> Nissa | AJ6: 20119
Q7: 45939 | R7: 45971 | V7: 3.27 | X7: 3.27 | Z7: Karen | AA7: 20120 | AB7: =IF(AC7<>"",_xlfn.TEXTBEFORE(AC7," ("),"") -> 20119 | AC7: 20119 (ID: 20119) | AD7: 20121 | AE7: 0 | AF7: Nissa | AG7: 20120 | AI7: =IF(AJ7="","",IF(_xlfn.XLOOKUP(AJ7,$AA$2:$AA$26,$Z$2:$Z$26,"")=0,"",_xlfn.XLOOKUP(AJ7,$AA$2:$AA$26,$Z$2:$Z$26,""))) -> Karen | AJ7: 20120
B8: Abandonment: | C8: =IFERROR(_xlfn.XLOOKUP($C$1,'Call Activity'!O:O,'Call Activity'!K:K)/100,"") -> 0.0678 | F8: Weekly Abandonment: | G8: =IFERROR(AVERAGE(W:W)/100,"") -> 0.04122 | Q8: 45940 | R8: 45978 | V8: 3.25 | X8: 3.25 | Z8: Serena | AA8: 20121 | AB8: =IF(AC8<>"",_xlfn.TEXTBEFORE(AC8," ("),"") -> 20120 | AC8: 20120 (ID: 20120) | AD8: 20122 | AE8: 0 | AF8: Ruth | AG8: 20121 | AI8: =IF(AJ8="","",IF(_xlfn.XLOOKUP(AJ8,$AA$2:$AA$26,$Z$2:$Z$26,"")=0,"",_xlfn.XLOOKUP(AJ8,$AA$2:$AA$26,$Z$2:$Z$26,""))) -> Serena | AJ8: 20121
B9: Monthly Average: | C9: =IFERROR(AVERAGE($V:$V)/100,"0.00%") -> 0.045653333 | F9: Monthly Average: | G9: =IFERROR(AVERAGE($X:$X)/100,"0.00%") -> 0.04154 | Q9: 45943 | R9: 45999 | V9: 3.94 | X9: 3.94 | Z9: Allison | AA9: 20122 | AB9: =IF(AC9<>"",_xlfn.TEXTBEFORE(AC9," ("),"") -> 20121 | AC9: 20121 (ID: 20121) | AD9: 20124 | AE9: 0 | AF9: Serena | AG9: 20122 | AI9: =IF(AJ9="","",IF(_xlfn.XLOOKUP(AJ9,$AA$2:$AA$26,$Z$2:$Z$26,"")=0,"",_xlfn.XLOOKUP(AJ9,$AA$2:$AA$26,$Z$2:$Z$26,""))) -> Allison | AJ9: 20122
Q10: 45944 | R10: 45992 | V10: 3.13 | X10: 3.13 | Z10: Teri | AA10: 20124 | AB10: =IF(AC10<>"",_xlfn.TEXTBEFORE(AC10," ("),"") -> 20122 | AC10: 20122 (ID: 20122) | AE10: 0 | AF10: Teri | AG10: 20124 | AI10: =IF(AJ10="","",IF(_xlfn.XLOOKUP(AJ10,$AA$2:$AA$26,$Z$2:$Z$26,"")=0,"",_xlfn.XLOOKUP(AJ10,$AA$2:$AA$26,$Z$2:$Z$26,""))) -> Teri | AJ10: 20124
B11: {=IFERROR( _xlfn._xlws.SORT( _xlfn.UNIQUE( _xlfn._xlws.FILTER( 'Agent Activity'!R:R, ('Agent Activity'!O:O = C1) * ('Agent Activity'!R:R <> "") * ('Agent Activity'!R:R <> 0) ) ) ), "No match" )} -> Allison | C11: {=IFERROR(IF(B11<>0, INDEX('Agent Activity'!$C:$C, MATCH(1, ('Agent Activity'!$R:$R=B11)*('Agent Activity'!$O:$O=$C$1), 0)), ""),"")} -> 3 | F11: {=IFERROR( _xlfn._xlws.SORT( _xlfn.UNIQUE( _xlfn._xlws.FILTER( 'Agent Activity'!R:R, ('Agent Activity'!Q:Q = G1) * ('Agent Activity'!R:R <> "") * ('Agent Activity'!R:R <> 0) ) ) ), "No match" )} -> Allison | G11: =IFERROR(IF(F11<>0,SUMIFS('Agent Activity'!$C:$C, 'Agent Activity'!$R:$R, F11, 'Agent Activity'!$Q:$Q, $G$1),""),"") -> 41 | Q11: 45945 | R11: 46006 | V11: 11.17 | AB11: =IF(AC11<>"",_xlfn.TEXTBEFORE(AC11," ("),"") -> 20124 | AC11: 20124 (ID: 20124) | AE11: 0 | AI11: =IF(AJ11="","",IF(_xlfn.XLOOKUP(AJ11,$AA$2:$AA$26,$Z$2:$Z$26,"")=0,"",_xlfn.XLOOKUP(AJ11,$AA$2:$AA$26,$Z$2:$Z$26,"")))
B12: Karen | C12: {=IF(B12<>0, INDEX('Agent Activity'!$C:$C, MATCH(1, ('Agent Activity'!$R:$R=B12)*('Agent Activity'!$O:$O=$C$1), 0)), "")} -> 11 | F12: Grey | G12: =IF(F12<>0,SUMIFS('Agent Activity'!$C:$C, 'Agent Activity'!$R:$R, F12, 'Agent Activity'!$Q:$Q, $G$1),"") -> 157 | Q12: 45946 | V12: 1.16 | AB12: =IF(AC12<>"",_xlfn.TEXTBEFORE(AC12," ("),"") | AE12: 0 | AI12: =IF(AJ12="","",IF(_xlfn.XLOOKUP(AJ12,$AA$2:$AA$26,$Z$2:$Z$26,"")=0,"",_xlfn.XLOOKUP(AJ12,$AA$2:$AA$26,$Z$2:$Z$26,"")))
B13: Nicole | C13: {=IF(B13<>0, INDEX('Agent Activity'!$C:$C, MATCH(1, ('Agent Activity'!$R:$R=B13)*('Agent Activity'!$O:$O=$C$1), 0)), "")} -> 12 | F13: Karen | G13: =IF(F13<>0,SUMIFS('Agent Activity'!$C:$C, 'Agent Activity'!$R:$R, F13, 'Agent Activity'!$Q:$Q, $G$1),"") -> 30 | Q13: 45947 | V13: 3.92 | AB13: =IF(AC13<>"",_xlfn.TEXTBEFORE(AC13," ("),"") | AE13: 0 | AI13: =IF(AJ13="","",IF(_xlfn.XLOOKUP(AJ13,$AA$2:$AA$26,$Z$2:$Z$26,"")=0,"",_xlfn.XLOOKUP(AJ13,$AA$2:$AA$26,$Z$2:$Z$26,"")))
B14: Nissa | C14: {=IF(B14<>0, INDEX('Agent Activity'!$C:$C, MATCH(1, ('Agent Activity'!$R:$R=B14)*('Agent Activity'!$O:$O=$C$1), 0)), "")} -> 26 | F14: Nicole | G14: =IF(F14<>0,SUMIFS('Agent Activity'!$C:$C, 'Agent Activity'!$R:$R, F14, 'Agent Activity'!$Q:$Q, $G$1),"") -> 48 | Q14: 45950 | V14: 3.91 | AB14: =IF(AC14<>"",_xlfn.TEXTBEFORE(AC14," ("),"") | AE14: 0 | AI14: =IF(AJ14="","",IF(_xlfn.XLOOKUP(AJ14,$AA$2:$AA$26,$Z$2:$Z$26,"")=0,"",_xlfn.XLOOKUP(AJ14,$AA$2:$AA$26,$Z$2:$Z$26,"")))
B15: Ruth | C15: {=IF(B15<>0, INDEX('Agent Activity'!$C:$C, MATCH(1, ('Agent Activity'!$R:$R=B15)*('Agent Activity'!$O:$O=$C$1), 0)), "")} -> 44 | F15: Nissa | G15: =IF(F15<>0,SUMIFS('Agent Activity'!$C:$C, 'Agent Activity'!$R:$R, F15, 'Agent Activity'!$Q:$Q, $G$1),"") -> 105 | Q15: 45951 | V15: 6.78 | AB15: =IF(AC15<>"",_xlfn.TEXTBEFORE(AC15," ("),"") | AE15: 0 | AI15: =IF(AJ15="","",IF(_xlfn.XLOOKUP(AJ15,$AA$2:$AA$26,$Z$2:$Z$26,"")=0,"",_xlfn.XLOOKUP(AJ15,$AA$2:$AA$26,$Z$2:$Z$26,"")))
B16: Teri | C16: {=IF(B16<>0, INDEX('Agent Activity'!$C:$C, MATCH(1, ('Agent Activity'!$R:$R=B16)*('Agent Activity'!$O:$O=$C$1), 0)), "")} -> 12 | F16: Ruth | G16: =IF(F16<>0,SUMIFS('Agent Activity'!$C:$C, 'Agent Activity'!$R:$R, F16, 'Agent Activity'!$Q:$Q, $G$1),"") -> 161 | Q16: 45953 | AB16: =IF(AC16<>"",_xlfn.TEXTBEFORE(AC16," ("),"") | AE16: 0 | AI16: =IF(AJ16="","",IF(_xlfn.XLOOKUP(AJ16,$AA$2:$AA$26,$Z$2:$Z$26,"")=0,"",_xlfn.XLOOKUP(AJ16,$AA$2:$AA$26,$Z$2:$Z$26,"")))
C17: {=IF(B17<>0, INDEX('Agent Activity'!$C:$C, MATCH(1, ('Agent Activity'!$R:$R=B17)*('Agent Activity'!$O:$O=$C$1), 0)), "")} | F17: Serena | G17: =IF(F17<>0,SUMIFS('Agent Activity'!$C:$C, 'Agent Activity'!$R:$R, F17, 'Agent Activity'!$Q:$Q, $G$1),"") -> 80 | Q17: 45954 | AB17: =IF(AC17<>"",_xlfn.TEXTBEFORE(AC17," ("),"") | AI17: =IF(AJ17="","",IF(_xlfn.XLOOKUP(AJ17,$AA$2:$AA$26,$Z$2:$Z$26,"")=0,"",_xlfn.XLOOKUP(AJ17,$AA$2:$AA$26,$Z$2:$Z$26,"")))
C18: {=IF(B18<>0, INDEX('Agent Activity'!$C:$C, MATCH(1, ('Agent Activity'!$R:$R=B18)*('Agent Activity'!$O:$O=$C$1), 0)), "")} | F18: Teri | G18: =IF(F18<>0,SUMIFS('Agent Activity'!$C:$C, 'Agent Activity'!$R:$R, F18, 'Agent Activity'!$Q:$Q, $G$1),"") -> 90 | Q18: 45957 | AB18: =IF(AC18<>"",_xlfn.TEXTBEFORE(AC18," ("),"") | AI18: =IF(AJ18="","",IF(_xlfn.XLOOKUP(AJ18,$AA$2:$AA$26,$Z$2:$Z$26,"")=0,"",_xlfn.XLOOKUP(AJ18,$AA$2:$AA$26,$Z$2:$Z$26,"")))
C19: {=IF(B19<>0, INDEX('Agent Activity'!$C:$C, MATCH(1, ('Agent Activity'!$R:$R=B19)*('Agent Activity'!$O:$O=$C$1), 0)), "")} | G19: =IF(F19<>0,SUMIFS('Agent Activity'!$C:$C, 'Agent Activity'!$R:$R, F19, 'Agent Activity'!$Q:$Q, $G$1),"") | Q19: 45958 | AB19: =IF(AC19<>"",_xlfn.TEXTBEFORE(AC19," ("),"") | AI19: =IF(AJ19="","",IF(_xlfn.XLOOKUP(AJ19,$AA$2:$AA$26,$Z$2:$Z$26,"")=0,"",_xlfn.XLOOKUP(AJ19,$AA$2:$AA$26,$Z$2:$Z$26,"")))
C20: {=IF(B20<>0, INDEX('Agent Activity'!$C:$C, MATCH(1, ('Agent Activity'!$R:$R=B20)*('Agent Activity'!$O:$O=$C$1), 0)), "")} | G20: =IF(F20<>0,SUMIFS('Agent Activity'!$C:$C, 'Agent Activity'!$R:$R, F20, 'Agent Activity'!$Q:$Q, $G$1),"") | Q20: 45959 | AB20: =IF(AC20<>"",_xlfn.TEXTBEFORE(AC20," ("),"") | AI20: =IF(AJ20="","",IF(_xlfn.XLOOKUP(AJ20,$AA$2:$AA$26,$Z$2:$Z$26,"")=0,"",_xlfn.XLOOKUP(AJ20,$AA$2:$AA$26,$Z$2:$Z$26,"")))
C21: {=IF(B21<>0, INDEX('Agent Activity'!$C:$C, MATCH(1, ('Agent Activity'!$R:$R=B21)*('Agent Activity'!$O:$O=$C$1), 0)), "")} | G21: =IF(F21<>0,SUMIFS('Agent Activity'!$C:$C, 'Agent Activity'!$R:$R, F21, 'Agent Activity'!$Q:$Q, $G$1),"") | Q21: 45960 | AB21: =IF(AC21<>"",_xlfn.TEXTBEFORE(AC21," ("),"") | AI21: =IF(AJ21="","",IF(_xlfn.XLOOKUP(AJ21,$AA$2:$AA$26,$Z$2:$Z$26,"")=0,"",_xlfn.XLOOKUP(AJ21,$AA$2:$AA$26,$Z$2:$Z$26,"")))
C22: {=IF(B22<>0, INDEX('Agent Activity'!$C:$C, MATCH(1, ('Agent Activity'!$R:$R=B22)*('Agent Activity'!$O:$O=$C$1), 0)), "")} | G22: =IF(F22<>0,SUMIFS('Agent Activity'!$C:$C, 'Agent Activity'!$R:$R, F22, 'Agent Activity'!$Q:$Q, $G$1),"") | Q22: 45961 | AB22: =IF(AC22<>"",_xlfn.TEXTBEFORE(AC22," ("),"") | AI22: =IF(AJ22="","",IF(_xlfn.XLOOKUP(AJ22,$AA$2:$AA$26,$Z$2:$Z$26,"")=0,"",_xlfn.XLOOKUP(AJ22,$AA$2:$AA$26,$Z$2:$Z$26,"")))
C23: {=IF(B23<>0, INDEX('Agent Activity'!$C:$C, MATCH(1, ('Agent Activity'!$R:$R=B23)*('Agent Activity'!$O:$O=$C$1), 0)), "")} | G23: =IF(F23<>0,SUMIFS('Agent Activity'!$C:$C, 'Agent Activity'!$R:$R, F23, 'Agent Activity'!$Q:$Q, $G$1),"") | Q23: 45964 | AB23: =IF(AC23<>"",_xlfn.TEXTBEFORE(AC23," ("),"") | AI23: =IF(AJ23="","",IF(_xlfn.XLOOKUP(AJ23,$AA$2:$AA$26,$Z$2:$Z$26,"")=0,"",_xlfn.XLOOKUP(AJ23,$AA$2:$AA$26,$Z$2:$Z$26,"")))
C24: {=IF(B24<>0, INDEX('Agent Activity'!$C:$C, MATCH(1, ('Agent Activity'!$R:$R=B24)*('Agent Activity'!$O:$O=$C$1), 0)), "")} | G24: =IF(F24<>0,SUMIFS('Agent Activity'!$C:$C, 'Agent Activity'!$R:$R, F24, 'Agent Activity'!$Q:$Q, $G$1),"") | Q24: 45965 | AB24: =IF(AC24<>"",_xlfn.TEXTBEFORE(AC24," ("),"") | AI24: =IF(AJ24="","",IF(_xlfn.XLOOKUP(AJ24,$AA$2:$AA$26,$Z$2:$Z$26,"")=0,"",_xlfn.XLOOKUP(AJ24,$AA$2:$AA$26,$Z$2:$Z$26,"")))
C25: {=IF(B25<>0, INDEX('Agent Activity'!$C:$C, MATCH(1, ('Agent Activity'!$R:$R=B25)*('Agent Activity'!$O:$O=$C$1), 0)), "")} | G25: =IF(F25<>0,SUMIFS('Agent Activity'!$C:$C, 'Agent Activity'!$R:$R, F25, 'Agent Activity'!$Q:$Q, $G$1),"") | Q25: 45966 | AB25: =IF(AC25<>"",_xlfn.TEXTBEFORE(AC25," ("),"") | AI25: =IF(AJ25="","",IF(_xlfn.XLOOKUP(AJ25,$AA$2:$AA$26,$Z$2:$Z$26,"")=0,"",_xlfn.XLOOKUP(AJ25,$AA$2:$AA$26,$Z$2:$Z$26,"")))
C26: {=IF(B26<>0, INDEX('Agent Activity'!$C:$C, MATCH(1, ('Agent Activity'!$R:$R=B26)*('Agent Activity'!$O:$O=$C$1), 0)), "")} | G26: =IF(F26<>0,SUMIFS('Agent Activity'!$C:$C, 'Agent Activity'!$R:$R, F26, 'Agent Activity'!$Q:$Q, $G$1),"") | Q26: 45967 | AB26: =IF(AC26<>"",_xlfn.TEXTBEFORE(AC26," ("),"") | AI26: =IF(AJ26="","",IF(_xlfn.XLOOKUP(AJ26,$AA$2:$AA$26,$Z$2:$Z$26,"")=0,"",_xlfn.XLOOKUP(AJ26,$AA$2:$AA$26,$Z$2:$Z$26,"")))
Q27: 45968
Q28: 45971
Q29: 45972
Q30: 45973
B31: =IF(B3<>0,_xlfn.TEXTJOIN(" ",FALSE,B3:C3),"") -> Calls In: 118 | F31: =IF(F3<>0,_xlfn.TEXTJOIN(" ",FALSE,F3:G3),"") -> Calls In: 712 | Q31: 45974
B32: =IF(B4<>0,_xlfn.TEXTJOIN(" ",FALSE,B4:C4),"") -> Abandoned: 8 | F32: =IF(F4<>0,_xlfn.TEXTJOIN(" ",FALSE,F4:G4),"") -> Abandoned: 29 | Q32: 45975
B33: =IF(B5<>0,_xlfn.TEXTJOIN(" ",FALSE,B5:C5),"") -> Calls Out: 99 | F33: =IF(F5<>0,_xlfn.TEXTJOIN(" ",FALSE,F5:G5),"") -> Calls Out: 673 | Q33: 45978
B34: =IF(B6<>0,_xlfn.TEXTJOIN(" ",FALSE,B6:C6),"") -> Total Calls: 209 | F34: =IF(F6<>0,_xlfn.TEXTJOIN(" ",FALSE,F6:G6),"") -> Total Calls: 1385 | Q34: 45979
B35: =IF(B7<>0,_xlfn.TEXTJOIN(" ",FALSE,B7:C7),"") | F35: =IF(F7<>0,_xlfn.TEXTJOIN(" ",FALSE,F7:G7),"") | Q35: 45981
B36: =_xlfn.TEXTJOIN(" ",FALSE,B8,TEXT(C8,"0.00%")) -> Abandonment: 6.78% | F36: =_xlfn.TEXTJOIN(" ",FALSE,F8,TEXT(G8,"0.00%")) -> Weekly Abandonment: 4.12% | Q36: 45982
B37: =_xlfn.TEXTJOIN(" ",FALSE,B9,TEXT(C9,"0.00%")) -> Monthly Average: 4.57% | F37: =_xlfn.TEXTJOIN(" ",FALSE,F9,TEXT(G9,"0.00%")) -> Monthly Average: 4.15% | Q37: 45999
B38: =IF(B10<>0,_xlfn.TEXTJOIN(" ",FALSE,B10:C10),"") | F38: =IF(F10<>0,_xlfn.TEXTJOIN(" ",FALSE,F10:G10),"") | Q38: 46000
B39: =IF(B11<>0,_xlfn.TEXTJOIN(" ",FALSE,B11:C11),"") -> Allison 3 | F39: =IF(F11<>0,_xlfn.TEXTJOIN(" ",FALSE,F11:G11),"") -> Allison 41 | Q39: 46001
B40: =IF(B12<>0,_xlfn.TEXTJOIN(" ",FALSE,B12:C12),"") -> Karen 11 | F40: =IF(F12<>0,_xlfn.TEXTJOIN(" ",FALSE,F12:G12),"") -> Grey 157 | Q40: 46002
...

Sheet Generator
A1: Initialized? | B1: 1
A2: Call Activity:
A3: Agent Activity:
A4: Calls Waiting:

Sheet Call Activity
A1: Agents | B1: Total | C1: # Ans. | D1: ASA | E1: LWC | F1: %GOS | G1: Avg. Talk Dur | H1: Tot. Talk Dur | I1: Avg. Handle | J1: # Aban | K1: % Aban | L1: Total | M1: Avg. Talk Dur | N1: Tot. Talk Dur | O1: Date | P1: Month | Q1: Week | R1: Baseline
A2: 0 | B2: 0 | C2: 0 | D2: 0 | E2: 0 | F2: 0 | G2: 0 | H2: 0 | I2: 0 | J2: 0 | K2: 0 | L2: 0 | M2: 0 | N2: v 4.1.2 | O2: 36892 | P2: January | Q2: 36892 | R2: 5
A3: 4.31 | B3: 130 | C3: 121 | D3: 0.00041666667 | E3: 0.0023263889 | F3: 71.65 | G3: 0.0023148148 | H3: 0.28023148 | I3: 0.005787037 | J3: 9 | K3: 6.92 | L3: 107 | M3: 0.0015393519 | N3: 0.16427083 | O3: 45931 | P3: October | Q3: 45929 | R3: 5
A4: 4.99 | B4: 119 | C4: 116 | D4: 0.00033564815 | E4: 0.0050694444 | F4: 82.2 | G4: 0.0017824074 | H4: 0.20731481 | I4: 0.0057986111 | J4: 3 | K4: 2.52 | L4: 109 | M4: 0.0010763889 | N4: 0.11773148 | O4: 45932 | P4: October | Q4: 45929 | R4: 5
A5: 1.61 | B5: 243 | C5: 236 | D5: 0.00046296296 | E5: 0.0050694444 | F5: 78.33 | G5: 0.0019675926 | H5: 0.46417824 | I5: 0.0055671296 | J5: 7 | K5: 2.88 | L5: 188 | M5: 0.0012152778 | N5: 0.22740741 | O5: 45933 | P5: October | Q5: 45929 | R5: 5
A6: 3.34 | B6: 185 | C6: 177 | D6: 0.00040509259 | E6: 0.025520833 | F6: 74.18 | G6: 0.0020833333 | H6: 0.36907407 | I6: 0.0055092593 | J6: 8 | K6: 4.32 | L6: 155 | M6: 0.0015740741 | N6: 0.24335648 | O6: 45936 | P6: October | Q6: 45936 | R6: 5
A7: 3.35 | B7: 137 | C7: 124 | D7: 0.00042824074 | E7: 0.0037962963 | F7: 79.2 | G7: 0.0020949074 | H7: 0.26021991 | I7: 0.0061458333 | J7: 13 | K7: 9.49 | L7: 177 | M7: 0.0010300926 | N7: 0.18240741 | O7: 45937 | P7: October | Q7: 45936 | R7: 5
A8: 2.49 | B8: 131 | C8: 127 | D8: 0.00050925926 | E8: 0.0040277778 | F8: 68.22 | G8: 0.0022337963 | H8: 0.28313657 | I8: 0.0041782407 | J8: 4 | K8: 3.05 | L8: 83 | M8: 0.0014467593 | N8: 0.11976852 | O8: 45938 | P8: October | Q8: 45936 | R8: 5
A9: 4.68 | B9: 149 | C9: 137 | D9: 0.00052083333 | E9: 0.0044907407 | F9: 68.75 | G9: 0.0020833333 | H9: 0.28481481 | I9: 0.0056481481 | J9: 12 | K9: 8.05 | L9: 231 | M9: 0.0011574074 | N9: 0.26815972 | O9: 45939 | P9: October | Q9: 45936 | R9: 5
A10: 5.01 | B10: 125 | C10: 120 | D10: 0.00050925926 | E10: 0.0034143519 | F10: 71.54 | G10: 0.0019444444 | H10: 0.23298611 | I10: 0.0059953704 | J10: 5 | K10: 4 | L10: 164 | M10: 0.001400463 | N10: 0.22931713 | O10: 45940 | P10: October | Q10: 45936 | R10: 5
A11: 4.15 | B11: 157 | C11: 156 | D11: 0.00021990741 | E11: 0.0039236111 | F11: 90.38 | G11: 0.0020138889 | H11: 0.31418981 | I11: 0.0041898148 | J11: 1 | K11: 0.64 | L11: 176 | M11: 0.0012962963 | N11: 0.22891204 | O11: 45943 | P11: October | Q11: 45943 | R11: 5
A12: 4.73 | B12: 139 | C12: 136 | D12: 0.00034722222 | E12: 0.0034027778 | F12: 83.82 | G12: 0.0021296296 | H12: 0.29012731 | I12: 0.0051273148 | J12: 3 | K12: 2.16 | L12: 140 | M12: 0.0014583333 | N12: 0.20405093 | O12: 45944 | P12: October | Q12: 45943 | R12: 5
A13: 3.93 | B13: 135 | C13: 134 | D13: 0.00024305556 | E13: 0.002662037 | F13: 90.3 | G13: 0.002025463 | H13: 0.2708912 | I13: 0.0063657407 | J13: 1 | K13: 0.74 | L13: 141 | M13: 0.0015625 | N13: 0.22009259 | O13: 45945 | P13: October | Q13: 45943 | R13: 5
A14: 3.87 | B14: 153 | C14: 145 | D14: 0.00054398148 | E14: 0.0028125 | F14: 66.44 | G14: 0.0022337963 | H14: 0.32393519 | I14: 0.0053819444 | J14: 8 | K14: 5.23 | L14: 121 | M14: 0.0012962963 | N14: 0.15708333 | O14: 45946 | P14: October | Q14: 45943 | R14: 5
... A54: 5.15 | B54: 102 | C54: 98 | D54: 0.00039351852 | E54: 0.0046759259 | F54: 86 | G54: 0.0018634259 | H54: 0.18238426 | I54: 0.0047685185 | J54: 4 | K54: 3.92 | L54: 71 | M54: 0.001099537 | N54: 0.077731481 | O54: 46008 | P54: December | Q54: 46006 | R54: 5
A55: 6.2 | B55: 128 | C55: 123 | D55: 0.00027777778 | E55: 0.0018981481 | F55: 80 | G55: 0.0019675926 | H55: 0.24219907 | I55: 0.0065740741 | J55: 5 | K55: 3.91 | L55: 144 | M55: 0.0013657407 | N55: 0.19650463 | O55: 46009 | P55: =TEXT(O55,"mmmm") -> December | Q55: =O55-WEEKDAY(O55,1)+2 -> 46006 | R55: 5
A56: 4.37 | B56: 118 | C56: 110 | D56: 0.00054398148 | E56: 0.0064351852 | F56: 73.04 | G56: 0.0023842593 | H56: 0.261875 | I56: 0.0071759259 | J56: 8 | K56: 6.78 | L56: 99 | M56: 0.0015277778 | N56: 0.15119213 | O56: 46010 | P56: =TEXT(O56,"mmmm") -> December | Q56: =O56-WEEKDAY(O56,1)+2 -> 46006 | R56: 5

Sheet Agent Activity
A1: ACD Incoming | I1: Work | L1: Break | O1: Sort
A2: ID | B2: Logon | C2: Incoming | D2: Average | E2: Total | I2: Work | J2: Average | K2: Total | L2: Break | M2: Average | N2: v 4.1.2
A3: Staff | B3: Duration | C3: # Ans. | D3: Talk Dur | E3: Talk Dur | F3: # Ans. | G3: Talk Dur | H3: Talk Dur | I3: Count | J3: Duration | K3: Duration | L3: Count | M3: Duration | N3: Duration | O3: Date | P3: Month | Q3: Week | R3: User
A4: 0 | B4: 0 | C4: 0 | D4: 0 | E4: 0 | I4: 0 | J4: 0 | K4: 0 | L4: 0 | M4: 0 | N4: 0 | O4: 0 | P4: =TEXT(O4,"mmmm") -> January | Q4: =O4-WEEKDAY(O4,1)+2 -> -5 | R4: {=IFERROR( _xlfn.LET( _xlpm.cleaned, TRIM(SUBSTITUTE(A4,CHAR(160)," ")), _xlpm.key, LEFT(_xlpm.cleaned, FIND(" (", _xlpm.cleaned & " (") - 1), _xlpm.lookupArray, TRIM(SUBSTITUTE(Huddle!$AA$2:$AA$25,CHAR(160)," ")), _xlpm.resultRange, Huddle!$Z$2:$Z$25, INDEX(_xlpm.resultRange, MATCH(_xlpm.key, _xlpm.lookupArray, 0)) ), "")}
A5: 20113 (ID: 20113) | B5: 0.15755787 | C5: 20 | D5: 0.0020023148 | E5: 0.04005787 | F5: 0 | G5: 0 | H5: 0 | I5: 26 | J5: 0.00033564815 | K5: 0.008599537 | L5: 3 | M5: 0.0049652778 | N5: 0.014907407 | O5: 45933 | P5: =TEXT(O5,"mmmm") -> October | Q5: =O5-WEEKDAY(O5,1)+2 -> 45929 | R5: {=IFERROR( _xlfn.LET( _xlpm.cleaned, TRIM(SUBSTITUTE(A5,CHAR(160)," ")), _xlpm.key, LEFT(_xlpm.cleaned, FIND(" (", _xlpm.cleaned & " (") - 1), _xlpm.lookupArray, TRIM(SUBSTITUTE(Huddle!$AA$2:$AA$25,CHAR(160)," ")), _xlpm.resultRange, Huddle!$Z$2:$Z$25, INDEX(_xlpm.resultRange, MATCH(_xlpm.key, _xlpm.lookupArray, 0)) ), "")} -> Ruth
A6: 20113 (ID: 20113) | B6: 0.33585648 | C6: 61 | D6: 0.0020717593 | E6: 0.12621528 | F6: 3 | G6: 0.0023148148 | H6: 0.0069444444 | I6: 59 | J6: 0.00030092593 | K6: 0.017430556 | L6: 3 | M6: 0.011597222 | N6: 0.034791667 | O6: 45936 | P6: =TEXT(O6,"mmmm") -> October | Q6: =O6-WEEKDAY(O6,1)+2 -> 45936 | R6: {=IFERROR( _xlfn.LET( _xlpm.cleaned, TRIM(SUBSTITUTE(A6,CHAR(160)," ")), _xlpm.key, LEFT(_xlpm.cleaned, FIND(" (", _xlpm.cleaned & " (") - 1), _xlpm.lookupArray, TRIM(SUBSTITUTE(Huddle!$AA$2:$AA$25,CHAR(160)," ")), _xlpm.resultRange, Huddle!$Z$2:$Z$25, INDEX(_xlpm.resultRange, MATCH(_xlpm.key, _xlpm.lookupArray, 0)) ), "")} -> Ruth
A7: 20113 (ID: 20113) | B7: 0.275 | C7: 33 | D7: 0.0027314815 | E7: 0.090011574 | F7: 0 | G7: 0 | H7: 0 | I7: 49 | J7: 0.0003587963 | K7: 0.01755787 | L7: 6 | M7: 0.0040740741 | N7: 0.024456019 | O7: 45937 | P7: =TEXT(O7,"mmmm") -> October | Q7: =O7-WEEKDAY(O7,1)+2 -> 45936 | R7: {=IFERROR( _xlfn.LET( _xlpm.cleaned, TRIM(SUBSTITUTE(A7,CHAR(160)," ")), _xlpm.key, LEFT(_xlpm.cleaned, FIND(" (", _xlpm.cleaned & " (") - 1), _xlpm.lookupArray, TRIM(SUBSTITUTE(Huddle!$AA$2:$AA$25,CHAR(160)," ")), _xlpm.resultRange, Huddle!$Z$2:$Z$25, INDEX(_xlpm.resultRange, MATCH(_xlpm.key, _xlpm.lookupArray, 0)) ), "")} -> Ruth
A8: 20113 (ID: 20113) | B8: 0.31662037 | C8: 48 | D8: 0.0021180556 | E8: 0.10157407 | F8: 2 | G8: 0.001712963 | H8: 0.0034259259 | I8: 68 | J8: 0.00038194444 | K8: 0.025787037 | L8: 6 | M8: 0.0033796296 | N8: 0.020300926 | O8: 45938 | P8: =TEXT(O8,"mmmm") -> October | Q8: =O8-WEEKDAY(O8,1)+2 -> 45936 | R8: {=IFERROR( _xlfn.LET( _xlpm.cleaned, TRIM(SUBSTITUTE(A8,CHAR(160)," ")), _xlpm.key, LEFT(_xlpm.cleaned, FIND(" (", _xlpm.cleaned & " (") - 1), _xlpm.lookupArray, TRIM(SUBSTITUTE(Huddle!$AA$2:$AA$25,CHAR(160)," ")), _xlpm.resultRange, Huddle!$Z$2:$Z$25, INDEX(_xlpm.resultRange, MATCH(_xlpm.key, _xlpm.lookupArray, 0)) ), "")} -> Ruth
A9: 20113 (ID: 20113) | B9: 0.30368056 | C9: 33 | D9: 0.0018402778 | E9: 0.060914352 | F9: 2 | G9: 0.00064814815 | H9: 0.0013078704 | I9: 66 | J9: 0.00068287037 | K9: 0.045324074 | L9: 7 | M9: 0.0037847222 | N9: 0.026527778 | O9: 45939 | P9: =TEXT(O9,"mmmm") -> October | Q9: =O9-WEEKDAY(O9,1)+2 -> 45936 | R9: {=IFERROR( _xlfn.LET( _xlpm.cleaned, TRIM(SUBSTITUTE(A9,CHAR(160)," ")), _xlpm.key, LEFT(_xlpm.cleaned, FIND(" (", _xlpm.cleaned & " (") - 1), _xlpm.lookupArray, TRIM(SUBSTITUTE(Huddle!$AA$2:$AA$25,CHAR(160)," ")), _xlpm.resultRange, Huddle!$Z$2:$Z$25, INDEX(_xlpm.resultRange, MATCH(_xlpm.key, _xlpm.lookupArray, 0)) ), "")} -> Ruth
A10: 20113 (ID: 20113) | B10: 0.32201389 | C10: 34 | D10: 0.0023032407 | E10: 0.078402778 | F10: 2 | G10: 0.00082175926 | H10: 0.0016435185 | I10: 68 | J10: 0.00038194444 | K10: 0.025868056 | L10: 7 | M10: 0.0032407407 | N10: 0.022719907 | O10: 45940 | P10: =TEXT(O10,"mmmm") -> October | Q10: =O10-WEEKDAY(O10,1)+2 -> 45936 | R10: {=IFERROR( _xlfn.LET( _xlpm.cleaned, TRIM(SUBSTITUTE(A10,CHAR(160)," ")), _xlpm.key, LEFT(_xlpm.cleaned, FIND(" (", _xlpm.cleaned & " (") - 1), _xlpm.lookupArray, TRIM(SUBSTITUTE(Huddle!$AA$2:$AA$25,CHAR(160)," ")), _xlpm.resultRange, Huddle!$Z$2:$Z$25, INDEX(_xlpm.resultRange, MATCH(_xlpm.key, _xlpm.lookupArray, 0)) ), "")} -> Ruth
A11: 20113 (ID: 20113) | B11: 0.33719907 | C11: 45 | D11: 0.0023032407 | E11: 0.10385417 | F11: 2 | G11: 0.0032175926 | H11: 0.0064467593 | I11: 74 | J11: 0.00028935185 | K11: 0.021446759 | L11: 6 | M11: 0.0039583333 | N11: 0.023784722 | O11: 45943 | P11: =TEXT(O11,"mmmm") -> October | Q11: =O11-WEEKDAY(O11,1)+2 -> 45943 | R11: {=IFERROR( _xlfn.LET( _xlpm.cleaned, TRIM(SUBSTITUTE(A11,CHAR(160)," ")), _xlpm.key, LEFT(_xlpm.cleaned, FIND(" (", _xlpm.cleaned & " (") - 1), _xlpm.lookupArray, TRIM(SUBSTITUTE(Huddle!$AA$2:$AA$25,CHAR(160)," ")), _xlpm.resultRange, Huddle!$Z$2:$Z$25, INDEX(_xlpm.resultRange, MATCH(_xlpm.key, _xlpm.lookupArray, 0)) ), "")} -> Ruth
A12: 20113 (ID: 20113) | B12: 0.30841435 | C12: 38 | D12: 0.0023032407 | E12: 0.087326389 | F12: 1 | G12: 0.00027777778 | H12: 0.00027777778 | I12: 51 | J12: 0.0003587963 | K12: 0.01837963 | L12: 6 | M12: 0.0030671296 | N12: 0.018402778 | O12: 45944 | P12: =TEXT(O12,"mmmm") -> October | Q12: =O12-WEEKDAY(O12,1)+2 -> 45943 | R12: {=IFERROR( _xlfn.LET( _xlpm.cleaned, TRIM(SUBSTITUTE(A12,CHAR(160)," ")), _xlpm.key, LEFT(_xlpm.cleaned, FIND(" (", _xlpm.cleaned & " (") - 1), _xlpm.lookupArray, TRIM(SUBSTITUTE(Huddle!$AA$2:$AA$25,CHAR(160)," ")), _xlpm.resultRange, Huddle!$Z$2:$Z$25, INDEX(_xlpm.resultRange, MATCH(_xlpm.key, _xlpm.lookupArray, 0)) ), "")} -> Ruth
A13: 20113 (ID: 20113) | B13: 0.31640046 | C13: 36 | D13: 0.0021759259 | E13: 0.078368056 | F13: 0 | G13: 0 | H13: 0 | I13: 68 | J13: 0.0003587963 | K13: 0.024085648 | L13: 7 | M13: 0.0035763889 | N13: 0.02505787 | O13: 45945 | P13: =TEXT(O13,"mmmm") -> October | Q13: =O13-WEEKDAY(O13,1)+2 -> 45943 | R13: {=IFERROR( _xlfn.LET( _xlpm.cleaned, TRIM(SUBSTITUTE(A13,CHAR(160)," ")), _xlpm.key, LEFT(_xlpm.cleaned, FIND(" (", _xlpm.cleaned & " (") - 1), _xlpm.lookupArray, TRIM(SUBSTITUTE(Huddle!$AA$2:$AA$25,CHAR(160)," ")), _xlpm.resultRange, Huddle!$Z$2:$Z$25, INDEX(_xlpm.resultRange, MATCH(_xlpm.key, _xlpm.lookupArray, 0)) ), "")} -> Ruth
A14: 20113 (ID: 20113) | B14: 0.32478009 | C14: 51 | D14: 0.0021180556 | E14: 0.10789352 | F14: 0 | G14: 0 | H14: 0 | I14: 74 | J14: 0.00056712963 | K14: 0.042048611 | L14: 7 | M14: 0.0050694444 | N14: 0.035474537 | O14: 45946 | P14: =TEXT(O14,"mmmm") -> October | Q14: =O14-WEEKDAY(O14,1)+2 -> 45943 | R14: {=IFERROR( _xlfn.LET( _xlpm.cleaned, TRIM(SUBSTITUTE(A14,CHAR(160)," ")), _xlpm.key, LEFT(_xlpm.cleaned, FIND(" (", _xlpm.cleaned & " (") - 1), _xlpm.lookupArray, TRIM(SUBSTITUTE(Huddle!$AA$2:$AA$25,CHAR(160)," ")), _xlpm.resultRange, Huddle!$Z$2:$Z$25, INDEX(_xlpm.resultRange, MATCH(_xlpm.key, _xlpm.lookupArray, 0)) ), "")} -> Ruth
A15: 20113 (ID: 20113) | B15: 0.30902778 | C15: 38 | D15: 0.0022800926 | E15: 0.086840278 | F15: 0 | G15: 0 | H15: 0 | I15: 47 | J15: 0.00032407407 | K15: 0.014988426 | L15: 9 | M15: 0.0024652778 | N15: 0.022164352 | O15: 45947 | P15: =TEXT(O15,"mmmm") -> October | Q15: =O15-WEEKDAY(O15,1)+2 -> 45943 | R15: {=IFERROR( _xlfn.LET( _xlpm.cleaned, TRIM(SUBSTITUTE(A15,CHAR(160)," ")), _xlpm.key, LEFT(_xlpm.cleaned, FIND(" (", _xlpm.cleaned & " (") - 1), _xlpm.lookupArray, TRIM(SUBSTITUTE(Huddle!$AA$2:$AA$25,CHAR(160)," ")), _xlpm.resultRange, Huddle!$Z$2:$Z$25, INDEX(_xlpm.resultRange, MATCH(_xlpm.key, _xlpm.lookupArray, 0)) ), "")} -> Ruth
A16: 20113 (ID: 20113) | B16: 0.32793981 | C16: 50 | D16: 0.002962963 | E16: 0.14833333 | F16: 2 | G16: 0.0026273148 | H16: 0.0052546296 | I16: 71 | J16: 0.00039351852 | K16: 0.028090278 | L16: 7 | M16: 0.0036111111 | N16: 0.02525463 | O16: 45950 | P16: =TEXT(O16,"mmmm") -> October | Q16: =O16-WEEKDAY(O16,1)+2 -> 45950 | R16: {=IFERROR( _xlfn.LET( _xlpm.cleaned, TRIM(SUBSTITUTE(A16,CHAR(160)," ")), _xlpm.key, LEFT(_xlpm.cleaned, FIND(" (", _xlpm.cleaned & " (") - 1), _xlpm.lookupArray, TRIM(SUBSTITUTE(Huddle!$AA$2:$AA$25,CHAR(160)," ")), _xlpm.resultRange, Huddle!$Z$2:$Z$25, INDEX(_xlpm.resultRange, MATCH(_xlpm.key, _xlpm.lookupArray, 0)) ), "")} -> Ruth
... A241: 20124 (ID: 20124) | B241: 0.28253472 | C241: 13 | D241: 0.0011921296 | E241: 0.015532407 | F241: 0 | G241: 0 | H241: 0 | I241: 52 | J241: 0.0013310185 | K241: 0.069074074 | L241: 1 | M241: 0.0066087963 | N241: 0.0066087963 | O241: 45981 | P241: =TEXT(O241,"mmmm") -> November | Q241: =O241-WEEKDAY(O241,1)+2 -> 45978 | R241: {=IFERROR( _xlfn.LET( _xlpm.cleaned, TRIM(SUBSTITUTE(A241,CHAR(160)," ")), _xlpm.key, LEFT(_xlpm.cleaned, FIND(" (", _xlpm.cleaned & " (") - 1), _xlpm.lookupArray, TRIM(SUBSTITUTE(Huddle!$AA$2:$AA$25,CHAR(160)," ")), _xlpm.resultRange, Huddle!$Z$2:$Z$25, INDEX(_xlpm.resultRange, MATCH(_xlpm.key, _xlpm.lookupArray, 0)) ), "")} -> Teri
A242: 20118 (ID: 20118) | B242: 0.33537037 | C242: 40 | D242: 0.0012847222 | E242: 0.051608796 | F242: 0 | G242: 0 | H242: 0 | I242: 87 | J242: 0.00068287037 | K242: 0.059375 | L242: 3 | M242: 0.0057291667 | N242: 0.017175926 | O242: 45982 | P242: =TEXT($O242,"mmmm") -> November | Q242: =$O242-WEEKDAY($O242,1)+2 -> 45978 | R242: {=IFERROR( _xlfn.LET( _xlpm.cleaned, TRIM(SUBSTITUTE(A242,CHAR(160)," ")), _xlpm.key, LEFT(_xlpm.cleaned, FIND(" (", _xlpm.cleaned & " (") - 1), _xlpm.lookupArray, TRIM(SUBSTITUTE(Huddle!$AA$2:$AA$25,CHAR(160)," ")), _xlpm.resultRange, Huddle!$Z$2:$Z$25, INDEX(_xlpm.resultRange, MATCH(_xlpm.key, _xlpm.lookupArray, 0)) ), "")} -> Nicole
A243: 20119 (ID: 20119) | B243: 0.16363426 | C243: 9 | D243: 0.0019097222 | E243: 0.0171875 | F243: 0 | G243: 0 | H243: 0 | I243: 30 | J243: 0.00071759259 | K243: 0.021377315 | L243: 5 | M243: 0.0036921296 | N243: 0.0184375 | O243: 45982 | P243: =TEXT($O243,"mmmm") -> November | Q243: =$O243-WEEKDAY($O243,1)+2 -> 45978 | R243: {=IFERROR( _xlfn.LET( _xlpm.cleaned, TRIM(SUBSTITUTE(A243,CHAR(160)," ")), _xlpm.key, LEFT(_xlpm.cleaned, FIND(" (", _xlpm.cleaned & " (") - 1), _xlpm.lookupArray, TRIM(SUBSTITUTE(Huddle!$AA$2:$AA$25,CHAR(160)," ")), _xlpm.resultRange, Huddle!$Z$2:$Z$25, INDEX(_xlpm.resultRange, MATCH(_xlpm.key, _xlpm.lookupArray, 0)) ), "")} -> Nissa
A244: 20121 (ID: 20121) | B244: 0.32884259 | C244: 33 | D244: 0.0017708333 | E244: 0.058263889 | F244: 0 | G244: 0 | H244: 0 | I244: 53 | J244: 0.00077546296 | K244: 0.040844907 | L244: 0 | M244: 0 | N244: 0 | O244: 45982 | P244: =TEXT($O244,"mmmm") -> November | Q244: =$O244-WEEKDAY($O244,1)+2 -> 45978 | R244: {=IFERROR( _xlfn.LET( _xlpm.cleaned, TRIM(SUBSTITUTE(A244,CHAR(160)," ")), _xlpm.key, LEFT(_xlpm.cleaned, FIND(" (", _xlpm.cleaned & " (") - 1), _xlpm.lookupArray, TRIM(SUBSTITUTE(Huddle!$AA$2:$AA$25,CHAR(160)," ")), _xlpm.resultRange, Huddle!$Z$2:$Z$25, INDEX(_xlpm.resultRange, MATCH(_xlpm.key, _xlpm.lookupArray, 0)) ), "")} -> Serena
A245: 20122 (ID: 20122) | B245: 0.31237269 | C245: 15 | D245: 0.0024421296 | E245: 0.036631944 | F245: 0 | G245: 0 | H245: 0 | I245: 34 | J245: 0.0045601852 | K245: 0.15506944 | L245: 1 | M245: 0.0038310185 | N245: 0.0038310185 | O245: 45982 | P245: =TEXT($O245,"mmmm") -> November | Q245: =$O245-WEEKDAY($O245,1)+2 -> 45978 | R245: {=IFERROR( _xlfn.LET( _xlpm.cleaned, TRIM(SUBSTITUTE(A245,CHAR(160)," ")), _xlpm.key, LEFT(_xlpm.cleaned, FIND(" (", _xlpm.cleaned & " (") - 1), _xlpm.lookupArray, TRIM(SUBSTITUTE(Huddle!$AA$2:$AA$25,CHAR(160)," ")), _xlpm.resultRange, Huddle!$Z$2:$Z$25, INDEX(_xlpm.resultRange, MATCH(_xlpm.key, _xlpm.lookupArray, 0)) ), "")} -> Allison
A246: 20113 (ID: 20113) | B246: 0.3121412 | C246: 39 | D246: 0.0020486111 | E246: 0.079953704 | F246: 1 | G246: 0.0012037037 | H246: 0.0012037037 | I246: 74 | J246: 0.00047453704 | K246: 0.03505787 | L246: 7 | M246: 0.0047800926 | N246: 0.033483796 | O246: 45999 | P246: =TEXT($O246,"mmmm") -> December | Q246: =$O246-WEEKDAY($O246,1)+2 -> 45999 | R246: {=IFERROR( _xlfn.LET( _xlpm.cleaned, TRIM(SUBSTITUTE(A246,CHAR(160)," ")), _xlpm.key, LEFT(_xlpm.cleaned, FIND(" (", _xlpm.cleaned & " (") - 1), _xlpm.lookupArray, TRIM(SUBSTITUTE(Huddle!$AA$2:$AA$25,CHAR(160)," ")), _xlpm.resultRange, Huddle!$Z$2:$Z$25, INDEX(_xlpm.resultRange, MATCH(_xlpm.key, _xlpm.lookupArray, 0)) ), "")} -> Ruth
A247: 20113 (ID: 20113) | B247: 0.28652778 | C247: 43 | D247: 0.0018402778 | E247: 0.078935185 | F247: 0 | G247: 0 | H247: 0 | I247: 77 | J247: 0.00034722222 | K247: 0.027094907 | L247: 9 | M247: 0.0027893519 | N247: 0.025150463 | O247: 46000 | P247: =TEXT($O247,"mmmm") -> December | Q247: =$O247-WEEKDAY($O247,1)+2 -> 45999 | R247: {=IFERROR( _xlfn.LET( _xlpm.cleaned, TRIM(SUBSTITUTE(A247,CHAR(160)," ")), _xlpm.key, LEFT(_xlpm.cleaned, FIND(" (", _xlpm.cleaned & " (") - 1), _xlpm.lookupArray, TRIM(SUBSTITUTE(Huddle!$AA$2:$AA$25,CHAR(160)," ")), _xlpm.resultRange, Huddle!$Z$2:$Z$25, INDEX(_xlpm.resultRange, MATCH(_xlpm.key, _xlpm.lookupArray, 0)) ), "")} -> Ruth
A248: 20113 (ID: 20113) | B248: 0.32662037 | C248: 25 | D248: 0.0020717593 | E248: 0.05181713 | F248: 0 | G248: 0 | H248: 0 | I248: 57 | J248: 0.00038194444 | K248: 0.021458333 | L248: 10 | M248: 0.0020717593 | N248: 0.020740741 | O248: 46001 | P248: =TEXT($O248,"mmmm") -> December | Q248: =$O248-WEEKDAY($O248,1)+2 -> 45999 | R248: {=IFERROR( _xlfn.LET( _xlpm.cleaned, TRIM(SUBSTITUTE(A248,CHAR(160)," ")), _xlpm.key, LEFT(_xlpm.cleaned, FIND(" (", _xlpm.cleaned & " (") - 1), _xlpm.lookupArray, TRIM(SUBSTITUTE(Huddle!$AA$2:$AA$25,CHAR(160)," ")), _xlpm.resultRange, Huddle!$Z$2:$Z$25, INDEX(_xlpm.resultRange, MATCH(_xlpm.key, _xlpm.lookupArray, 0)) ), "")} -> Ruth
A249: 20113 (ID: 20113) | B249: 0.31804398 | C249: 28 | D249: 0.0022106481 | E249: 0.061863426 | F249: 1 | G249: 3.4722222e-05 | H249: 3.4722222e-05 | I249: 51 | J249: 0.00034722222 | K249: 0.017824074 | L249: 7 | M249: 0.0034027778 | N249: 0.023796296 | O249: 46002 | P249: =TEXT($O249,"mmmm") -> December | Q249: =$O249-WEEKDAY($O249,1)+2 -> 45999 | R249: {=IFERROR( _xlfn.LET( _xlpm.cleaned, TRIM(SUBSTITUTE(A249,CHAR(160)," ")), _xlpm.key, LEFT(_xlpm.cleaned, FIND(" (", _xlpm.cleaned & " (") - 1), _xlpm.lookupArray, TRIM(SUBSTITUTE(Huddle!$AA$2:$AA$25,CHAR(160)," ")), _xlpm.resultRange, Huddle!$Z$2:$Z$25, INDEX(_xlpm.resultRange, MATCH(_xlpm.key, _xlpm.lookupArray, 0)) ), "")} -> Ruth
A250: 20113 (ID: 20113) | B250: 0.31609954 | C250: 26 | D250: 0.0016435185 | E250: 0.04275463 | F250: 0 | G250: 0 | H250: 0 | I250: 62 | J250: 0.00047453704 | K250: 0.029201389 | L250: 7 | M250: 0.0027777778 | N250: 0.019444444 | O250: 46003 | P250: =TEXT($O250,"mmmm") -> December | Q250: =$O250-WEEKDAY($O250,1)+2 -> 45999 | R250: {=IFERROR( _xlfn.LET( _xlpm.cleaned, TRIM(SUBSTITUTE(A250,CHAR(160)," ")), _xlpm.key, LEFT(_xlpm.cleaned, FIND(" (", _xlpm.cleaned & " (") - 1), _xlpm.lookupArray, TRIM(SUBSTITUTE(Huddle!$AA$2:$AA$25,CHAR(160)," ")), _xlpm.resultRange, Huddle!$Z$2:$Z$25, INDEX(_xlpm.resultRange, MATCH(_xlpm.key, _xlpm.lookupArray, 0)) ), "")} -> Ruth
A251: 20116 (ID: 20116) | B251: 0.36648148 | C251: 38 | D251: 0.0017939815 | E251: 0.068043981 | F251: 0 | G251: 0 | H251: 0 | I251: 38 | J251: 0.00028935185 | K251: 0.010949074 | L251: 27 | M251: 0.0040972222 | N251: 0.1105787 | O251: 45999 | P251: =TEXT($O251,"mmmm") -> December | Q251: =$O251-WEEKDAY($O251,1)+2 -> 45999 | R251: {=IFERROR( _xlfn.LET( _xlpm.cleaned, TRIM(SUBSTITUTE(A251,CHAR(160)," ")), _xlpm.key, LEFT(_xlpm.cleaned, FIND(" (", _xlpm.cleaned & " (") - 1), _xlpm.lookupArray, TRIM(SUBSTITUTE(Huddle!$AA$2:$AA$25,CHAR(160)," ")), _xlpm.resultRange, Huddle!$Z$2:$Z$25, INDEX(_xlpm.resultRange, MATCH(_xlpm.key, _xlpm.lookupArray, 0)) ), "")} -> Grey
A252: 20116 (ID: 20116) | B252: 0.33533565 | C252: 29 | D252: 0.0022106481 | E252: 0.064074074 | F252: 1 | G252: 0.0011226852 | H252: 0.0011226852 | I252: 36 | J252: 0.00032407407 | K252: 0.011574074 | L252: 19 | M252: 0.0072337963 | N252: 0.1375463 | O252: 46000 | P252: =TEXT($O252,"mmmm") -> December | Q252: =$O252-WEEKDAY($O252,1)+2 -> 45999 | R252: {=IFERROR( _xlfn.LET( _xlpm.cleaned, TRIM(SUBSTITUTE(A252,CHAR(160)," ")), _xlpm.key, LEFT(_xlpm.cleaned, FIND(" (", _xlpm.cleaned & " (") - 1), _xlpm.lookupArray, TRIM(SUBSTITUTE(Huddle!$AA$2:$AA$25,CHAR(160)," ")), _xlpm.resultRange, Huddle!$Z$2:$Z$25, INDEX(_xlpm.resultRange, MATCH(_xlpm.key, _xlpm.lookupArray, 0)) ), "")} -> Grey
A253: 20116 (ID: 20116) | B253: 0.32356481 | C253: 32 | D253: 0.0018402778 | E253: 0.058761574 | F253: 1 | G253: 0.0015509259 | H253: 0.0015509259 | I253: 46 | J253: 0.00038194444 | K253: 0.017696759 | L253: 7 | M253: 0.0027083333 | N253: 0.018935185 | O253: 46001 | P253: =TEXT($O253,"mmmm") -> December | Q253: =$O253-WEEKDAY($O253,1)+2 -> 45999 | R253: {=IFERROR( _xlfn.LET( _xlpm.cleaned, TRIM(SUBSTITUTE(A253,CHAR(160)," ")), _xlpm.key, LEFT(_xlpm.cleaned, FIND(" (", _xlpm.cleaned & " (") - 1), _xlpm.lookupArray, TRIM(SUBSTITUTE(Huddle!$AA$2:$AA$25,CHAR(160)," ")), _xlpm.resultRange, Huddle!$Z$2:$Z$25, INDEX(_xlpm.resultRange, MATCH(_xlpm.key, _xlpm.lookupArray, 0)) ), "")} -> Grey
... A284: 20124 (ID: 20124) | B284: 0.29222222 | C284: 13 | D284: 0.0013888889 | E284: 0.018101852 | F284: 0 | G284: 0 | H284: 0 | I284: 48 | J284: 0.0021180556 | K284: 0.10142361 | L284: 0 | M284: 0 | N284: 0 | O284: 46003 | P284: =TEXT($O284,"mmmm") -> December | Q284: =$O284-WEEKDAY($O284,1)+2 -> 45999 | R284: {=IFERROR( _xlfn.LET( _xlpm.cleaned, TRIM(SUBSTITUTE(A284,CHAR(160)," ")), _xlpm.key, LEFT(_xlpm.cleaned, FIND(" (", _xlpm.cleaned & " (") - 1), _xlpm.lookupArray, TRIM(SUBSTITUTE(Huddle!$AA$2:$AA$25,CHAR(160)," ")), _xlpm.resultRange, Huddle!$Z$2:$Z$25, INDEX(_xlpm.resultRange, MATCH(_xlpm.key, _xlpm.lookupArray, 0)) ), "")} -> Teri
A285: 20124 (ID: 20124) | B285: 0.29222222 | C285: 13 | D285: 0.0013888889 | E285: 0.018101852 | F285: 0 | G285: 0 | H285: 0 | I285: 48 | J285: 0.0021180556 | K285: 0.10142361 | L285: 0 | M285: 0 | N285: 0 | O285: 46003 | P285: =TEXT($O285,"mmmm") -> December | Q285: =$O285-WEEKDAY($O285,1)+2 -> 45999 | R285: {=IFERROR(_xlfn.LET(_xlpm.cleaned,TRIM(SUBSTITUTE(A285,CHAR(160)," ")),_xlpm.key,LEFT(_xlpm.cleaned,FIND(" (", _xlpm.cleaned & " (") - 1),_xlpm.lookupArray,TRIM(SUBSTITUTE(Huddle!$AA$2:$AA$25,CHAR(160)," ")),_xlpm.resultRange,Huddle!$Z$2:$Z$25,INDEX(_xlpm.resultRange,MATCH(_xlpm.key, _xlpm.lookupArray, 0))),"")} -> Teri
A286: 20112 (ID: 20112) | B286: 0.10645833 | C286: 2 | D286: 0.00125 | E286: 0.0024884259 | F286: 0 | G286: 0 | H286: 0 | I286: 11 | J286: 0.0045138889 | K286: 0.0496875 | L286: 2 | M286: 0.0041898148 | N286: 0.0083796296 | O286: 45996 | P286: =TEXT($O286,"mmmm") -> December | Q286: =$O286-WEEKDAY($O286,1)+2 -> 45992 | R286: {=IFERROR(_xlfn.LET(_xlpm.cleaned,TRIM(SUBSTITUTE($A286,CHAR(160)," ")),_xlpm.key,LEFT(_xlpm.cleaned,FIND(" (",_xlpm.cleaned & " (")-1),_xlpm.lookupArray,TRIM(SUBSTITUTE(Huddle!$AA$2:$AA$25,CHAR(160)," ")),_xlpm.resultRange,Huddle!$Z$2:$Z$25,INDEX(_xlpm.resultRange,MATCH(_xlpm.key,_xlpm.lookupArray,0))),"")}
A287: 20113 (ID: 20113) | B287: 0.64637731 | C287: 64 | D287: 0.002974537 | E287: 0.19059028 | F287: 0 | G287: 0 | H287: 0 | I287: 81 | J287: 0.00043981481 | K287: 0.0359375 | L287: 7 | M287: 0.045972222 | N287: 0.32179398 | O287: 45992 | P287: =TEXT($O287,"mmmm") -> December | Q287: =$O287-WEEKDAY($O287,1)+2 -> 45992 | R287: {=IFERROR(_xlfn.LET(_xlpm.cleaned,TRIM(SUBSTITUTE($A287,CHAR(160)," ")),_xlpm.key,LEFT(_xlpm.cleaned,FIND(" (",_xlpm.cleaned & " (")-1),_xlpm.lookupArray,TRIM(SUBSTITUTE(Huddle!$AA$2:$AA$25,CHAR(160)," ")),_xlpm.resultRange,Huddle!$Z$2:$Z$25,INDEX(_xlpm.resultRange,MATCH(_xlpm.key,_xlpm.lookupArray,0))),"")} -> Ruth
A288: 20113 (ID: 20113) | B288: 0.64703704 | C288: 30 | D288: 0.0021296296 | E288: 0.063796296 | F288: 0 | G288: 0 | H288: 0 | I288: 72 | J288: 0.00043981481 | K288: 0.032025463 | L288: 14 | M288: 0.025925926 | N288: 0.36300926 | O288: 45993 | P288: =TEXT($O288,"mmmm") -> December | Q288: =$O288-WEEKDAY($O288,1)+2 -> 45992 | R288: {=IFERROR(_xlfn.LET(_xlpm.cleaned,TRIM(SUBSTITUTE($A288,CHAR(160)," ")),_xlpm.key,LEFT(_xlpm.cleaned,FIND(" (",_xlpm.cleaned & " (")-1),_xlpm.lookupArray,TRIM(SUBSTITUTE(Huddle!$AA$2:$AA$25,CHAR(160)," ")),_xlpm.resultRange,Huddle!$Z$2:$Z$25,INDEX(_xlpm.resultRange,MATCH(_xlpm.key,_xlpm.lookupArray,0))),"")} -> Ruth
A289: 20113 (ID: 20113) | B289: 0.30641204 | C289: 29 | D289: 0.0019675926 | E289: 0.057175926 | F289: 0 | G289: 0 | H289: 0 | I289: 89 | J289: 0.00041666667 | K289: 0.037002315 | L289: 6 | M289: 0.0026041667 | N289: 0.015648148 | O289: 45994 | P289: =TEXT($O289,"mmmm") -> December | Q289: =$O289-WEEKDAY($O289,1)+2 -> 45992 | R289: {=IFERROR(_xlfn.LET(_xlpm.cleaned,TRIM(SUBSTITUTE($A289,CHAR(160)," ")),_xlpm.key,LEFT(_xlpm.cleaned,FIND(" (",_xlpm.cleaned & " (")-1),_xlpm.lookupArray,TRIM(SUBSTITUTE(Huddle!$AA$2:$AA$25,CHAR(160)," ")),_xlpm.resultRange,Huddle!$Z$2:$Z$25,INDEX(_xlpm.resultRange,MATCH(_xlpm.key,_xlpm.lookupArray,0))),"")} -> Ruth
A290: 20113 (ID: 20113) | B290: 0.31783565 | C290: 22 | D290: 0.0027083333 | E290: 0.059525463 | F290: 2 | G290: 0.0022222222 | H290: 0.0044560185 | I290: 45 | J290: 0.00043981481 | K290: 0.019976852 | L290: 7 | M290: 0.0043287037 | N290: 0.030277778 | O290: 45995 | P290: =TEXT($O290,"mmmm") -> December | Q290: =$O290-WEEKDAY($O290,1)+2 -> 45992 | R290: {=IFERROR(_xlfn.LET(_xlpm.cleaned,TRIM(SUBSTITUTE($A290,CHAR(160)," ")),_xlpm.key,LEFT(_xlpm.cleaned,FIND(" (",_xlpm.cleaned & " (")-1),_xlpm.lookupArray,TRIM(SUBSTITUTE(Huddle!$AA$2:$AA$25,CHAR(160)," ")),_xlpm.resultRange,Huddle!$Z$2:$Z$25,INDEX(_xlpm.resultRange,MATCH(_xlpm.key,_xlpm.lookupArray,0))),"")} -> Ruth
A291: 20113 (ID: 20113) | B291: 0.32238426 | C291: 27 | D291: 0.0024652778 | E291: 0.0665625 | F291: 0 | G291: 0 | H291: 0 | I291: 65 | J291: 0.00038194444 | K291: 0.024872685 | L291: 8 | M291: 0.0033912037 | N291: 0.02712963 | O291: 45996 | P291: =TEXT($O291,"mmmm") -> December | Q291: =$O291-WEEKDAY($O291,1)+2 -> 45992 | R291: {=IFERROR(_xlfn.LET(_xlpm.cleaned,TRIM(SUBSTITUTE($A291,CHAR(160)," ")),_xlpm.key,LEFT(_xlpm.cleaned,FIND(" (",_xlpm.cleaned & " (")-1),_xlpm.lookupArray,TRIM(SUBSTITUTE(Huddle!$AA$2:$AA$25,CHAR(160)," ")),_xlpm.resultRange,Huddle!$Z$2:$Z$25,INDEX(_xlpm.resultRange,MATCH(_xlpm.key,_xlpm.lookupArray,0))),"")} -> Ruth
A292: 20116 (ID: 20116) | B292: 0.3244213 | C292: 35 | D292: 0.0013425926 | E292: 0.047152778 | F292: 1 | G292: 0.0018981481 | H292: 0.0018981481 | I292: 38 | J292: 0.00020833333 | K292: 0.0081018519 | L292: 26 | M292: 0.0047916667 | N292: 0.12456019 | O292: 45993 | P292: =TEXT($O292,"mmmm") -> December | Q292: =$O292-WEEKDAY($O292,1)+2 -> 45992 | R292: {=IFERROR(_xlfn.LET(_xlpm.cleaned,TRIM(SUBSTITUTE($A292,CHAR(160)," ")),_xlpm.key,LEFT(_xlpm.cleaned,FIND(" (",_xlpm.cleaned & " (")-1),_xlpm.lookupArray,TRIM(SUBSTITUTE(Huddle!$AA$2:$AA$25,CHAR(160)," ")),_xlpm.resultRange,Huddle!$Z$2:$Z$25,INDEX(_xlpm.resultRange,MATCH(_xlpm.key,_xlpm.lookupArray,0))),"")} -> Grey
A293: 20116 (ID: 20116) | B293: 0.35275463 | C293: 23 | D293: 0.0022337963 | E293: 0.051446759 | F293: 1 | G293: 0.0038541667 | H293: 0.0038541667 | I293: 28 | J293: 0.00018518519 | K293: 0.0053125 | L293: 16 | M293: 0.0065972222 | N293: 0.10564815 | O293: 45994 | P293: =TEXT($O293,"mmmm") -> December | Q293: =$O293-WEEKDAY($O293,1)+2 -> 45992 | R293: {=IFERROR(_xlfn.LET(_xlpm.cleaned,TRIM(SUBSTITUTE($A293,CHAR(160)," ")),_xlpm.key,LEFT(_xlpm.cleaned,FIND(" (",_xlpm.cleaned & " (")-1),_xlpm.lookupArray,TRIM(SUBSTITUTE(Huddle!$AA$2:$AA$25,CHAR(160)," ")),_xlpm.resultRange,Huddle!$Z$2:$Z$25,INDEX(_xlpm.resultRange,MATCH(_xlpm.key,_xlpm.lookupArray,0))),"")} -> Grey
A294: 20116 (ID: 20116) | B294: 0.26560185 | C294: 17 | D294: 0.0022800926 | E294: 0.038784722 | F294: 0 | G294: 0 | H294: 0 | I294: 21 | J294: 0.0002662037 | K294: 0.0056597222 | L294: 19 | M294: 0.0042476852 | N294: 0.080671296 | O294: 45995 | P294: =TEXT($O294,"mmmm") -> December | Q294: =$O294-WEEKDAY($O294,1)+2 -> 45992 | R294: {=IFERROR(_xlfn.LET(_xlpm.cleaned,TRIM(SUBSTITUTE($A294,CHAR(160)," ")),_xlpm.key,LEFT(_xlpm.cleaned,FIND(" (",_xlpm.cleaned & " (")-1),_xlpm.lookupArray,TRIM(SUBSTITUTE(Huddle!$AA$2:$AA$25,CHAR(160)," ")),_xlpm.resultRange,Huddle!$Z$2:$Z$25,INDEX(_xlpm.resultRange,MATCH(_xlpm.key,_xlpm.lookupArray,0))),"")} -> Grey
...

Sheet Sheet1
